Workbook
Name \1: #REF!
Name \a: #REF!
Name \c: #REF!
Name \D: #REF!
Name \E: #REF!
Name \F: #REF!
Name \H: #REF!
Name \i: #REF!
Name \J: #REF!
Name \l: #REF!
Name \M: #REF!
Name \P: #REF!
Name \q: #REF!
Name \R: #REF!
Name \T: #REF!
Name \U: #REF!
Name \w: #REF!
Name \x: #REF!
Name \z: #REF!
Name _: #REF!
Name __________________ff17: #REF!
Name _________________ff17: #REF!
Name ________________ff17: #REF!
Name _______________ff17: #REF!
Name _____________ff17: #REF!
Name ____________ff17: #REF!
Name ___________ff17: #REF!
Name __________ff17: #REF!
Name _________ff17: #REF!
Name ________ff17: #REF!
Name _______Cat1: #REF!
Name _______Cat2: #REF!
Name _______Cat3: #REF!
Name _______cat4: #REF!
Name _______Cat5: #REF!
Name _______cat6: #REF!
Name _______Cat7: #REF!
Name _______Cat8: #REF!
Name _______ff17: #REF!
Name ______Cat1: #REF!
Name ______Cat2: #REF!
Name ______Cat3: #REF!
Name ______cat4: #REF!
Name ______Cat5: #REF!
Name ______cat6: #REF!
Name ______Cat7: #REF!
Name ______Cat8: #REF!
Name ______F: #REF!
Name ______ff17: #REF!
Name ______PU1125: #REF!
Name _____Cat1: #REF!
Name _____Cat2: #REF!
Name _____Cat3: #REF!
Name _____cat4: #REF!
Name _____Cat5: #REF!
Name _____cat6: #REF!
Name _____Cat7: #REF!
Name _____Cat8: #REF!
Name _____F: #REF!
Name _____ff17: #REF!

Sheet Resumo
B2: Cenários - 10/12/2025 | D2: 46021 | E2: =EOMONTH(D2,1) -> 46053 | F2: =EOMONTH(E2,1) -> 46081 | G2: =EOMONTH(F2,1) -> 46112 | H2: Total | I2: Orçamento
B3: Posição comprada | C3: @ | D3: 81890 | E3: 110100 | F3: 142000 | G3: 71500 | H3: =SUM(D3:G3) -> 405490 | I3: 862666.67 | J3: =H3/I3 -> 0.4700425 | K3: Percentual sobre o total
B4: Exposição cenário BGI cotação 10/12/2025 | C4: @ | D4: 28130 | E4: 44100 | F4: 109000 | G4: 22000 | H4: =SUM(D4:G4) -> 203230 | I4: =H4/I3 -> 0.23558346
B5: Exposição cenário @ 350 | C5: @ | D5: -21370 | E5: -5400 | F5: 76000 | G5: -11000 | H5: =SUM(D5:G5) -> 38230 | I5: =H5/I3 -> 0.044316074
B6: Exposição cenário @ 300 | C6: @ | D6: 77630 | E6: 93600 | F6: 142000 | G6: 55000 | H6: =SUM(D6:G6) -> 368230 | I6: =H6/I3 -> 0.42685085
B8: Exposição x posição comprada | C8: %
B9: Exposição cenário BGI cotação 10/12/2025 | C9: % | D9: =D4/D$3 -> 0.34350959 | E9: =E4/E$3 -> 0.40054496 | F9: =F4/F$3 -> 0.76760563 | G9: =G4/G$3 -> 0.30769231 | H9: =AVERAGE(D9:G9) -> 0.45483812
B10: Exposição cenário @ 350 | C10: % | D10: =D5/D$3 -> -0.26095982 | E10: =E5/E$3 -> -0.049046322 | F10: =F5/F$3 -> 0.53521127 | G10: =G5/G$3 -> -0.15384615 | H10: =AVERAGE(D10:G10) -> 0.017839742
B11: Exposição cenário @ 300 | C11: % | D11: =D6/D$3 -> 0.947979 | E11: =E6/E$3 -> 0.85013624 | F11: =F6/F$3 -> 1 | G11: =G6/G$3 -> 0.76923077 | H11: =AVERAGE(D11:G11) -> 0.8918365
B13: Receita | I13: 3.0533293e+08
B14: Receita cenário BGI cotação 10/12/2025 | C14: R$ | D14: 27551281 | E14: 36826612 | F14: 46969900 | G14: 24119396 | H14: =SUM(D14:G14) -> 1.3546719e+08 | I14: =H14/I$13 -> 0.44367042
B15: Receita cenário @ 350 | C15: R$ | D15: 27635803 | E15: 37177792 | F15: 49003700 | G15: 24070996 | H15: =SUM(D15:G15) -> 1.3788829e+08 | I15: =H15/I$13 -> 0.45159981
B16: Receita cenário @ 300 | C16: R$ | D16: 25981803 | E16: 34725292 | F16: 43223700 | G16: 22640996 | H16: =SUM(D16:G16) -> 1.2657179e+08 | I16: =H16/I$13 -> 0.41453699
B18: P&L | I18: 34867031
B19: Resultado cenário BGI cotação 10/12/2025 | C19: R$ | D19: 1653662 | E19: 6692629.7 | F19: 12045417 | G19: -217931.19 | H19: =SUM(D19:G19) -> 20173778 | I19: =H19/I$18 -> 0.57859179
B20: Resultado cenário @ 350 | C20: R$ | D20: 1738184 | E20: 7043809.7 | F20: 14079217 | G20: -266331.19 | H20: =SUM(D20:G20) -> 22594880 | I20: =H20/I$18 -> 0.64802994
B21: Resultado cenário @ 300 | C21: R$ | D21: 84184.034 | E21: 4591309.7 | F21: 8299217.2 | G21: -1696331.2 | H21: =SUM(D21:G21) -> 11278380 | I21: =H21/I$18 -> 0.32346832

Sheet Inputs
B2: Preço médio | D2: =D72 -> 336.44256 | E2: =E72 -> 334.48331 | F2: =F72 -> 330.77394 | G2: =G72 -> 337.33422 | H2: =H72 -> #DIV/0! | I2: =I72 -> #DIV/0! | J2: =J72 -> #DIV/0! | K2: =K72 -> #DIV/0! | ... O2: =O72 -> #DIV/0!
B3: Gado | D3: 46021 | E3: =EOMONTH(D3,1) -> 46053 | F3: =EOMONTH(E3,1) -> 46081 | G3: =EOMONTH(F3,1) -> 46112 | H3: =EOMONTH(G3,1) -> 46142 | I3: =EOMONTH(H3,1) -> 46173 | J3: =EOMONTH(I3,1) -> 46203 | K3: =EOMONTH(J3,1) -> 46234 | L3: =EOMONTH(K3,1) -> 46265 | ... O3: =EOMONTH(N3,1) -> 46356
B4: Arrobas comprados | C4: @ | D4: =D6*D11 -> 36709.31 | E4: =E6*E11 -> 49355.172 | F4: =F6*F11 -> 63655.172 | G4: =G6*G11 -> 32051.724 | H4: =H6*H11 -> 0 | I4: =I6*I11 -> 0 | J4: =J6*J11 -> 0 | K4: =K6*K11 -> 0 | ... O4: =O6*O11 -> 0
B5: Arrobas produzidos | C5: @ | D5: =D6*D12 -> 45180.69 | E5: =E6*E12 -> 60744.828 | F5: =F6*F12 -> 78344.828 | G5: =G6*G12 -> 39448.276 | H5: =H6*H12 -> 0 | I5: =I6*I12 -> 0 | J5: =J6*J12 -> 0 | K5: =K6*K12 -> 0 | ... O5: =O6*O12 -> 0
B6: Arrobas totais | C6: @ | D6: =Base!V41*Inputs!D15 -> 81890 | E6: =Base!Y41*Inputs!E15 -> 110100 | F6: =Base!AB41*Inputs!E15 -> 142000 | G6: =Base!AE41*Inputs!F15 -> 71500
B7: Cabeças | C7: cb | D7: =D6/D10 -> 5118.125 | E7: =E6/E10 -> 6881.25 | F7: =F6/F10 -> 8875 | G7: =G6/G10 -> 4468.75 | H7: =H6/H10 -> 0 | I7: =I6/I10 -> 0 | J7: =J6/J10 -> 0 | K7: =K6/K10 -> 0 | ... O7: =O6/O10 -> 0 | P7: =SUM(D7:G7) -> 25343.125
B9: Compra | C9: @ | D9: 13 | E9: 13 | F9: 13 | G9: 13 | H9: 12 | I9: 12 | J9: 12 | K9: 12 | L9: 12 | M9: 12 | N9: 12 | O9: 12
B10: Abate | C10: @ | D10: 16 | E10: 16 | F10: 16 | G10: 16 | H10: 16 | I10: 16 | J10: 16 | K10: 16 | L10: 16 | M10: 16 | N10: 16 | O10: 16
B11: Compra | C11: @ | D11: =D9/SUM(D9:D10) -> 0.44827586 | E11: =E9/SUM(E9:E10) -> 0.44827586 | F11: =F9/SUM(F9:F10) -> 0.44827586 | G11: =G9/SUM(G9:G10) -> 0.44827586 | H11: =H9/SUM(H9:H10) -> 0.42857143 | I11: =I9/SUM(I9:I10) -> 0.42857143 | J11: =J9/SUM(J9:J10) -> 0.42857143 | K11: =K9/SUM(K9:K10) -> 0.42857143 | ... O11: =O9/SUM(O9:O10) -> 0.42857143
B12: Abate | C12: @ | D12: =D10/SUM(D9:D10) -> 0.55172414 | E12: =E10/SUM(E9:E10) -> 0.55172414 | F12: =F10/SUM(F9:F10) -> 0.55172414 | G12: =G10/SUM(G9:G10) -> 0.55172414 | H12: =H10/SUM(H9:H10) -> 0.57142857 | I12: =I10/SUM(I9:I10) -> 0.57142857 | J12: =J10/SUM(J9:J10) -> 0.57142857 | K12: =K10/SUM(K9:K10) -> 0.57142857 | ... O12: =O10/SUM(O9:O10) -> 0.57142857
B14: Vendas | D14: 46021 | E14: =EOMONTH(D14,1) -> 46053 | F14: =EOMONTH(E14,1) -> 46081 | G14: =EOMONTH(F14,1) -> 46112 | H14: =EOMONTH(G14,1) -> 46142 | I14: =EOMONTH(H14,1) -> 46173 | J14: =EOMONTH(I14,1) -> 46203 | K14: =EOMONTH(J14,1) -> 46234 | L14: =EOMONTH(K14,1) -> 46265 | ... O14: =EOMONTH(N14,1) -> 46356
B15: Conversão contratos -> arrobas | C15: x | D15: 330 | E15: 330 | F15: 330 | G15: 330 | H15: 330 | I15: 330 | J15: 330 | K15: 330 | L15: 330 | M15: 330 | N15: 330 | O15: 330
B16: Preço no fechamento | C16: R$/@ | D16: 320.6 | E16: 325.2 | F16: 326.8 | G16: 329.7 | H16: 327 | I16: 327 | J16: 327 | K16: 327 | L16: 327 | M16: 327 | N16: 327 | O16: 327
B17: Call
B18: Preço de strike | C18: R$/@ | D18: =Base!EE17 -> 335 | E18: =Base!EZ17 -> 335 | F18: =Base!FL17 -> 335 | G18: =Base!FO17 -> 335
B19: Contratos | C19: un | D19: =Base!EE19 -> -150 | E19: =Base!EZ19 -> -150 | F19: =Base!FL19 -> -100 | G19: =Base!FO19 -> -100
B20: Posição em arrobas | D20: =D19*D15 -> -49500 | E20: =E19*E15 -> -49500 | F20: =F19*F15 -> -33000 | G20: =G19*G15 -> -33000 | H20: =H19*H15 -> 0 | I20: =I19*I15 -> 0 | J20: =J19*J15 -> 0 | K20: =K19*K15 -> 0 | ... O20: =O19*O15 -> 0
B21: Data do strike | C21: data | D21: 46021 | E21: =EOMONTH(D21,1) -> 46053 | F21: =EOMONTH(E21,1) -> 46081 | G21: =EOMONTH(F21,1) -> 46112 | H21: =EOMONTH(G21,1) -> 46142 | I21: =EOMONTH(H21,1) -> 46173 | J21: =EOMONTH(I21,1) -> 46203 | K21: =EOMONTH(J21,1) -> 46234 | L21: =EOMONTH(K21,1) -> 46265 | ... O21: =EOMONTH(N21,1) -> 46356
B22: Prêmio | C22: R$/@ | D22: =Base!EE18 -> 6.9733333 | E22: =Base!EZ18 -> 9.09 | F22: =Base!FL18 -> 7 | G22: =Base!FO18 -> 8
B24: Receita prêmio | C24: R$ | D24: =-D22*D19*D15 -> 345180 | E24: =-E22*E19*E15 -> 449955 | F24: =-F22*F19*F15 -> 231000 | G24: =-G22*G19*G15 -> 264000 | H24: =-H22*H19*H15 -> 0 | I24: =-I22*I19*I15 -> 0 | J24: =-J22*J19*J15 -> 0 | K24: =-K22*K19*K15 -> 0 | ... O24: =-O22*O19*O15 -> 0
B25: Resultado preço | C25: R$ | D25: =(D16-D18)*D28*D15 -> 0 | E25: =(E16-E18)*E28*E15 -> 0 | F25: =(F16-F18)*F28*F15 -> 0 | G25: =(G16-G18)*G28*G15 -> 0 | H25: =(H16-H18)*H28*H15 -> 0 | I25: =(I16-I18)*I28*I15 -> 0 | J25: =(J16-J18)*J28*J15 -> 0 | K25: =(K16-K18)*K28*K15 -> 0 | ... O25: =(O16-O18)*O28*O15 -> 0
B26: Resultado | C26: R$ | D26: =SUM(D24:D25) -> 345180 | E26: =SUM(E24:E25) -> 449955 | F26: =SUM(F24:F25) -> 231000 | G26: =SUM(G24:G25) -> 264000 | H26: =SUM(H24:H25) -> 0 | I26: =SUM(I24:I25) -> 0 | J26: =SUM(J24:J25) -> 0 | K26: =SUM(K24:K25) -> 0 | ... O26: =SUM(O24:O25) -> 0
B28: Posição | C28: un | D28: =IF(D16>=D18,D19,0) -> 0 | E28: =IF(E16>=E18,E19,0) -> 0 | F28: =IF(F16>=F18,F19,0) -> 0 | G28: =IF(G16>=G18,G19,0) -> 0 | H28: =IF(H16>=H18,H19,0) -> 0 | I28: =IF(I16>=I18,I19,0) -> 0 | J28: =IF(J16>=J18,J19,0) -> 0 | K28: =IF(K16>=K18,K19,0) -> 0 | ... O28: =IF(O16>=O18,O19,0) -> 0
B29: Posição | C29: @ | D29: =D28*330 -> 0 | E29: =E28*330 -> 0 | F29: =F28*330 -> 0 | G29: =G28*330 -> 0 | H29: =H28*330 -> 0 | I29: =I28*330 -> 0 | J29: =J28*330 -> 0 | K29: =K28*330 -> 0 | ... O29: =O28*330 -> 0
B30: Custo do exercício | C30: R$ | D30: =(D29*D18)-(D29*D16) -> 0 | E30: =(E29*E18)-(E29*E16) -> 0 | F30: =(F29*F18)-(F29*F16) -> 0 | G30: =(G29*G18)-(G29*G16) -> 0 | H30: =(H29*H18)-(H29*H16) -> 0 | I30: =(I29*I18)-(I29*I16) -> 0 | J30: =(J29*J18)-(J29*J16) -> 0 | K30: =(K29*K18)-(K29*K16) -> 0 | ... O30: =(O29*O18)-(O29*O16) -> 0
B32: Put
B33: Preço de strike | C33: R$/@ | D33: =Base!EB17 -> 320 | E33: =Base!EW17 -> 320 | F33: =Base!FI17 -> 325 | G33: =Base!FR17 -> 325
B34: Contratos | C34: un | D34: =Base!EB19 -> -150 | E34: =Base!EW19 -> -150 | F34: =Base!FI19 -> -100 | G34: =Base!FR19 -> -100
B35: Posição em arrobas | D35: =D34*D15 -> -49500 | E35: =E34*E15 -> -49500 | F35: =F34*F15 -> -33000 | G35: =G34*G15 -> -33000 | H35: =H34*H15 -> 0 | I35: =I34*I15 -> 0 | J35: =J34*J15 -> 0 | K35: =K34*K15 -> 0 | ... O35: =O34*O15 -> 0
B36: Data do strike | C36: data | D36: 46021 | E36: 46053 | F36: 46081 | G36: 46112 | H36: 46112 | I36: 46112 | J36: 46112 | K36: 46112 | L36: 46112 | M36: 46112 | N36: 46112 | O36: 46112
B37: Preço no strike | C37: R$/@ | D37: =D16 -> 320.6 | E37: =E16 -> 325.2 | F37: =F16 -> 326.8 | G37: =G16 -> 329.7 | H37: =H16 -> 327 | I37: =I16 -> 327 | J37: =J16 -> 327 | K37: =K16 -> 327 | ... O37: =O16 -> 327
B38: Prêmio | C38: R$/@ | D38: =Base!EB18 -> 8.48 | E38: =Base!EW18 -> 7.9766667 | F38: =Base!FI18 -> 7.5 | G38: =Base!FR18 -> 8.5
B40: Receita prêmio | C40: R$ | D40: =-D38*D34*D15 -> 419760 | E40: =-E38*E34*E15 -> 394845 | F40: =-F38*F34*F15 -> 247500 | G40: =-G38*G34*G15 -> 280500 | H40: =-H38*H34*H15 -> 0 | I40: =-I38*I34*I15 -> 0 | J40: =-J38*J34*J15 -> 0 | K40: =-K38*K34*K15 -> 0 | ... O40: =-O38*O34*O15 -> 0
B41: Resultado preço | C41: R$ | D41: =(D37-D33)*D44*D15 -> 0 | E41: =(E37-E33)*E44*E15 -> 0 | F41: =(F37-F33)*F44*F15 -> 0 | G41: =(G37-G33)*G44*G15 -> 0 | H41: =(H37-H33)*H44*H15 -> 0 | I41: =(I37-I33)*I44*I15 -> 0 | J41: =(J37-J33)*J44*J15 -> 0 | K41: =(K37-K33)*K44*K15 -> 0 | ... O41: =(O37-O33)*O44*O15 -> 0
B42: Resultado | C42: R$ | D42: =SUM(D40:D41) -> 419760 | E42: =SUM(E40:E41) -> 394845 | F42: =SUM(F40:F41) -> 247500 | G42: =SUM(G40:G41) -> 280500 | H42: =SUM(H40:H41) -> 0 | I42: =SUM(I40:I41) -> 0 | J42: =SUM(J40:J41) -> 0 | K42: =SUM(K40:K41) -> 0 | ... O42: =SUM(O40:O41) -> 0
B44: Posição | C44: un | D44: =IF(D37<=D33,-D34,0) -> 0 | E44: =IF(E37<=E33,-E34,0) -> 0 | F44: =IF(F37<=F33,-F34,0) -> 0 | G44: =IF(G37<=G33,-G34,0) -> 0 | H44: =IF(H37<=H33,-H34,0) -> 0 | I44: =IF(I37<=I33,-I34,0) -> 0 | J44: =IF(J37<=J33,-J34,0) -> 0 | K44: =IF(K37<=K33,-K34,0) -> 0 | ... O44: =IF(O37<=O33,-O34,0) -> 0
B45: Posição | C45: @ | D45: =D44*330 -> 0 | E45: =E44*330 -> 0 | F45: =F44*330 -> 0 | G45: =G44*330 -> 0 | H45: =H44*330 -> 0 | I45: =I44*330 -> 0 | J45: =J44*330 -> 0 | K45: =K44*330 -> 0 | ... O45: =O44*330 -> 0
B46: Custo do exercício | C46: R$ | D46: =(D45*D16)-(D45*D33) -> 0 | E46: =(E45*E16)-(E45*E33) -> 0 | F46: =(F45*F16)-(F45*F33) -> 0 | G46: =(G45*G16)-(G45*G33) -> 0 | H46: =(H45*H16)-(H45*H33) -> 0 | I46: =(I45*I16)-(I45*I33) -> 0 | J46: =(J45*J16)-(J45*J33) -> 0 | K46: =(K45*K16)-(K45*K33) -> 0 | ... O46: =(O45*O16)-(O45*O33) -> 0
B48: Resultado call e put | C48: R$ | D48: =D42+D26 -> 764940 | E48: =E42+E26 -> 844800 | F48: =F42+F26 -> 478500 | G48: =G42+G26 -> 544500 | H48: =H42+H26 -> 0 | I48: =I42+I26 -> 0 | J48: =J42+J26 -> 0 | K48: =K42+K26 -> 0 | ... O48: =O42+O26 -> 0
B49: Posição call e put | C49: un | D49: =D44+D28 -> 0 | E49: =E44+E28 -> 0 | F49: =F44+F28 -> 0 | G49: =G44+G28 -> 0 | H49: =H44+H28 -> 0 | I49: =I44+I28 -> 0 | J49: =J44+J28 -> 0 | K49: =K44+K28 -> 0 | ... O49: =O44+O28 -> 0
...

Sheet Base
A1: Maio_25 | D1: Jun_25 | G1: Jul_25 | J1: Ago_25 | M1: Set_25 | P1: Oct_25 | S1: Nov_25 | V1: Dez_25 | Y1: Jan_26 | AB1: Fev_26 | AE1: Mar_26 | AH1: pnl mai_24 | AJ1: pnl Jun_24 | AL1: pnl jul_24 | AN1: pnl_ago_24 | AP1: pnl_set_24 | AR1: pnl_oct_24 | AT1: pnl_nov_24 | AV1: pnl_dez_24 | AX1: pnl_jan_25 | AZ1: pnl_fev_25 | BB1: pnl_mar_25 | BD1: Call_Jun_315 | BE1: 315 | BG1: Call_Jun_315 | BH1: 315 | BJ1: Put_Jun_315 | BK1: 315 | BM1: Call_Jul_330 | BN1: 330 | BP1: Put_Jul_330 | BQ1: 330 | BS1: Put_Jul_330 | BT1: 330 | BV1: Put_Aug_325 | BW1: 325 | BY1: Call_Aug_335 | BZ1: 335 | CB1: Call_Aug_325 | CC1: 325 | CE1: Put_Set_330 | CF1: 330 | CH1: Call_Set_330 | CI1: 330 | CK1: Call_Oct_248 | CL1: 248 | CN1: Put_Oct_330 | CO1: 330 | CQ1: Call_Oct_355 | CR1: 355 | CT1: Put_Oct_235 | CU1: 370 | CW1: Call_Oct_370 | CX1: 370 | CZ1: Call_Oct_250 | DA1: 250 | DC1: Call_Oct_250 | DD1: 250 | DF1: Call_Oct_250 | DG1: 245 | DI1: Put_Oct_257 | DJ1: 257 | DL1: Call_Oct_262 | DM1: 262 | DO1: Put_Nov_320 | DP1: 320 | DR1: Call_Nov_340 | DS1: 340 | DU1: Put_Nov_235 | DV1: 235 | DX1: Call_Nov_245 | DY1: 245 | EA1: Put_Dez_320 | EB1: 320 | ED1: Call_Dez_335 | EE1: 335 | EG1: Put_Dez_320 | EH1: 320 | EJ1: Call_Dez_335 | EK1: 335 | EM1: Put_Dez_275 | EN1: 275 | EP1: Put_Dez_297 | EQ1: 297 | ES1: Call_Dez_310 | ET1: 310 | EV1: Put_Jan_320 | EW1: 320 | EY1: Put_Jan_320 | EZ1: 320 | FB1: Call_Jan_335 | FC1: 335 | FE1: Call_Jan_335 | FF1: 335 | FH1: Put_Feb_325 | FI1: 325 | FK1: Call_Feb_335 | FL1: 335 | FN1: Call_Mar_335 | FO1: 335 | FQ1: Put_Mar_325 | FR1: 325
D2: 112 | E2: 318 | G2: -50 | H2: 330 | I2: Minerva | J2: =-16500/330 -> -50 | K2: 329.4 | L2: termo/rolagem | M2: -34 | N2: 315 | O2: BTG | P2: -103 | Q2: 341 | R2: BTG | S2: -100 | T2: 328.66 | U2: termo/Minerva | V2: -50 | W2: 321.81 | X2: termo/Minerva | Y2: -100 | Z2: 327.7 | AA2: boitel Eloi | AB2: -25 | AC2: 330 | AE2: -25 | AF2: 330.5 | AH2: 316 | AJ2: 316.4 | AL2: 295 | AN2: 312.1 | AP2: 304 | AR2: 318 | AT2: 320.25 | AV2: 320 | AX2: 323.75 | AZ2: 325.4 | BB2: 326
D3: 28 | E3: 319 | G3: -70 | H3: 303 | I3: BTG / Exercício | L3: termo/rolagem | P3: 1 | Q3: 345 | R3: BTG | S3: =-1348/330 -> -4.0848485 | T3: 329.89 | U3: termo/Minerva | V3: =-10200/330 -> -30.909091 | W3: 334.19 | X3: termo/Minerva | Y3: -65 | Z3: 328.65 | AA3: boitel Eloi | AB3: -15 | AC3: 338 | AD3: boitel gustavo | AE3: -26 | AF3: 330 | AH3: =(AH2-C27)*B27*330 -> #DIV/0! | AJ3: =(AJ2-E27)*D27*330 -> -85140 | AL3: =(AL2-H27)*G27*330 -> 2030344.8 | AN3: =(AN2-K27)*J27*330 -> 1216033.5 | AP3: =(AP2-N27)*M27*330 -> 1003464 | AR3: =(AR2-Q27)*P27*330+13000 -> 729098.75 | AT3: =(AT2-T27)*S27*330 -> 687594.72 | AV3: =(AV2-W27)*V27*330 -> 564663 | AX3: =(AX2-Z27)*Y27*330 -> 272992.5 | AZ3: =(AZ2-AC27)*AB27*330 -> 132000 | BB3: =(BB2-AF27)*AE27*330 -> 184496.4 | BD3: Spot | BE3: =$AJ$2 -> 316.4 | BG3: Spot | BH3: =$AJ$2 -> 316.4 | BJ3: Spot | BK3: =$AJ$2 -> 316.4 | BM3: Spot | BN3: =$AL$2 -> 295 | BP3: Spot | BQ3: =$AL$2 -> 295 | BS3: Spot | BT3: =$AL$2 -> 295 | BV3: Spot | BW3: =$AN$2 -> 312.1 | BY3: Spot | BZ3: =$AN$2 -> 312.1 | CB3: Spot | CC3: =$AN$2 -> 312.1 | CE3: Spot | CF3: =AP2 -> 304 | CH3: Spot | CI3: =$AP$2 -> 304 | CK3: Spot | CL3: =$AR$2 -> 318 | CN3: Spot | CO3: =$AR$2 -> 318 | CQ3: Spot | CR3: =$AR$2 -> 318 | CT3: Spot | CU3: =$AR$2 -> 318 | CW3: Spot | CX3: =$AR$2 -> 318 | CZ3: Spot | DA3: =$AR$2 -> 318 | DC3: Spot | DD3: =$AR$2 -> 318 | DF3: Spot | DG3: =$AR$2 -> 318 | DI3: Spot | DJ3: 260 | DL3: Spot | DM3: =$AR$2 -> 318 | DO3: Spot | DP3: =$AT$2 -> 320.25 | DR3: Spot | DS3: =$AT$2 -> 320.25 | DU3: Spot | DV3: =$AT$2 -> 320.25 | DX3: Spot | DY3: =$AT$2 -> 320.25 | EA3: Spot | EB3: =$AV$2 -> 320 | ED3: Spot | EE3: =$AV$2 -> 320 | EG3: Spot | EH3: =$AV$2 -> 320 | EJ3: Spot | EK3: =$AV$2 -> 320 | EM3: Spot | EN3: =$AV$2 -> 320 | EP3: Spot | EQ3: =$AV$2 -> 320 | ES3: Spot | ET3: =$AV$2 -> 320 | EV3: Spot | EW3: =$AX$2 -> 323.75 | EY3: Spot | EZ3: =$AX$2 -> 323.75 | FB3: Spot | FC3: =$AX$2 -> 323.75 | FE3: Spot | FF3: =$AX$2 -> 323.75 | FH3: Spot | FI3: =$AX$2 -> 323.75 | FK3: Spot | FL3: =$AX$2 -> 323.75 | FN3: Spot | FO3: =$BB$2 -> 326 | FQ3: Spot | FR3: =$BB$2 -> 326
D4: 60 | E4: 316.5 | G4: -100 | H4: =330-5.53 -> 324.47 | I4: Rolagem/Agosto | J4: =-6270/330 -> -19 | K4: 324.25 | L4: termo/rolagem | M4: -50 | N4: =330-6.61 -> 323.39 | O4: termo/rolagem | P4: 14 | Q4: 353 | R4: BTG | S4: -50 | T4: 336.3 | U4: termo/Minerva | V4: -75 | W4: 324 | X4: termo/Minerva | Y4: -35 | Z4: 327 | AA4: próprio | AB4: -60 | AC4: 327 | AE4: -25 | AF4: 329 | AJ4: zerado | FY4: Posição Física_Max + Estoques | GB4: Posição Hedge_Max | GF4: Valores Bolsa Alocado
G5: -25 | H5: =330.4-4.9 -> 325.5 | I5: Rolagem/Agosto | J5: =-4290/330 -> -13 | K5: 319 | L5: termo/rolagem | M5: 14 | N5: 308.7 | O5: BTG | P5: 25 | Q5: 338 | R5: BTG | S5: -35 | T5: 330 | U5: termo/Minerva | V5: -7 | W5: 328 | X5: boitel/Gustavo | AA5: 200 lotes direto | AE5: -49 | AF5: 329.42 | BD5: Notional | BE5: 330 | BG5: Notional | BH5: 330 | BJ5: Notional | BK5: 330 | BM5: Notional | BN5: 320 | BP5: Notional | BQ5: 330 | BS5: Notional | BT5: 330 | BV5: Notional | BW5: 330 | BY5: Notional | BZ5: 330 | CB5: Notional | CC5: 330 | CE5: Notional | CF5: 330 | CH5: Notional | CI5: 330 | CK5: Notional | CL5: 330 | CN5: Notional | CO5: 330 | CQ5: Notional | CR5: 330 | CT5: Notional | CU5: 330 | CW5: Notional | CX5: 330 | CZ5: Notional | DA5: 330 | DC5: Notional | DD5: 330 | DF5: Notional | DG5: 330 | DI5: Notional | DJ5: 330 | DL5: Notional | DM5: 330 | DO5: Notional | DP5: 330 | DR5: Notional | DS5: 330 | DU5: Notional | DV5: 330 | DX5: Notional | DY5: 330 | EA5: Notional | EB5: 330 | ED5: Notional | EE5: 330 | EG5: Notional | EH5: 330 | EJ5: Notional | EK5: 330 | EM5: Notional | EN5: 330 | EP5: Notional | EQ5: 330 | ES5: Notional | ET5: 330 | EV5: Notional | EW5: 330 | EY5: Notional | EZ5: 330 | FB5: Notional | FC5: 330 | FE5: Notional | FF5: 330 | FH5: Notional | FI5: 330 | FK5: Notional | FL5: 330 | FN5: Notional | FO5: 330 | FQ5: Notional | FR5: 330 | FY5: Cab | FZ5: =12000+3000+2000 -> 17000 | GB5: Cts | GC5: =(FZ6+FZ9)/330 -> 1087.1212 | GF5: Data | GG5: Confinamento | GH5: qtd cab | GI5: valor/cab | GJ5: valor $ | GK5: historico
G6: -45 | H6: 296.5 | I6: BTG / Exercício/Rol Aug | L6: verificar posição no jul | M6: 20 | N6: 324 | O6: BTG | P6: 25 | Q6: 334 | R6: BTG | S6: -7 | T6: 323 | U6: boitel/Gustavo | V6: -25 | W6: 330.5 | X6: corretora terra/frigol | AA6: com Frigol | AE6: -25 | AF6: 330 | FY6: (@) Média | FZ6: =FZ5*17.5 -> 297500 | GF6: 45425 | GG6: São Judas | GH6: 0 | GI6: 100 | GJ6: =GH6*GI6 -> 0 | GK6: Proprio - Pula Ano
G7: -8 | H7: 296.62 | J7: -51 | K7: 327.86961 | L7: termo/rolagem | M7: -45 | N7: =K16+7.5 -> 330.5 | O7: termo/rolagem | P7: 25 | Q7: 332 | R7: BTG | S7: =-20000/330 -> -60.606061 | T7: 319 | U7: termo/Minerva | V7: -25 | W7: 332.5 | X7: corretora terra/frigol | AA7: 324.3 | BD7: Cts | BE7: -298 | BG7: Cts | BH7: -25 | BJ7: Cts | BK7: -161 | BM7: Cts | BN7: -150 | BP7: Cts | BQ7: -55 | BS7: Cts | BT7: -150 | BV7: Cts | BW7: -200 | BY7: Cts | BZ7: -100 | CB7: Cts | CC7: -100 | CE7: Cts | CF7: -100 | CH7: Cts | CI7: -100 | CK7: Cts | CL7: 0 | CN7: Cts | CO7: -164 | CQ7: Cts | CR7: 400 | CT7: Cts | CU7: 0 | CW7: Cts | CX7: -800 | CZ7: Cts | DA7: 0 | DC7: Cts | DD7: 0 | DF7: Cts | DG7: 0 | DI7: Cts | DJ7: 0 | DL7: Cts | DM7: 0 | DO7: Cts | DP7: -50 | DR7: Cts | DS7: -50 | DU7: Cts | DV7: 0 | DX7: Cts | DY7: 0 | EA7: Cts | EB7: -100 | ED7: Cts | EE7: -100 | EG7: Cts | EH7: -50 | EJ7: Cts | EK7: -50 | EM7: Cts | EN7: 0 | EP7: Cts | EQ7: 0 | ES7: Cts | ET7: 0 | EV7: Cts | EW7: -100 | EY7: Cts | EZ7: -50 | FB7: Cts | FC7: -100 | FE7: Cts | FF7: -50 | FH7: Cts | FI7: -100 | FK7: Cts | FL7: -100 | FN7: Cts | FO7: -100 | FQ7: Cts | FR7: -100 | GB7: Posição Hedge_Atual
G8: -2 | H8: 294.55 | L8: verificar posição no jul | M8: 190 | N8: 315.59 | O8: BTG | P8: =-8580/330 -> -26 | Q8: 334.85 | R8: termo/rolagem | S8: -29 | T8: 325 | V8: 50 | W8: 315 | FY8: Cab_Estoque | FZ8: 3500 | GB8: Cts | GC8: =M27+P27+S27-54+G27+300 -> -664.97879
G9: -50 | H9: 295.62 | J9: -3 | K9: 326 | L9: BTG | M9: -50 | N9: 319 | O9: BTG | P9: =-990/330 -> -3 | Q9: 337.25 | R9: termo/rolagem | S9: 29 | T9: 321 | V9: -50 | W9: 320 | BD9: PnL | BE9: =IF(BE3>BE1,(BE3-BE1)*BE7*330+BE11,BE11) -> 133576.4 | BG9: PnL | BH9: =IF(BH3>BH1,(BH3-BH1)*BH7*330+BH11,BH11) -> 15675 | BJ9: PnL | BK9: =IF(BK3>BK1,BK11,(BK1-BK3)*BK7*330+BK11) -> 340032 | BM9: PnL | BN9: =IF(BN3>BN1,(BN3-BN1)*BN7*330+BN11,BN11) -> 278400 | BP9: PnL | BQ9: =IF(BQ3>BQ1,BQ11,(BQ1-BQ3)*BQ7*330+BQ11) -> -460420 | BS9: PnL | BT9: =IF(BT3>BT1,BT11,(BT1-BT3)*BT7*330+BT11) -> -1306800 | BV9: PnL | BW9: =IF(BW3>BW1,BW11,(BW1-BW3)*BW7*330+BW11) -> -409530 | BY9: PnL | BZ9: =IF(BZ3>BZ1,(BZ3-BZ1)*BZ7*330+BZ11,BZ11) -> 269280 | CB9: PnL | CC9: =IF(CC3>CC1,(CC3-CC1)*CC7*330+CC11,CC11) -> 182490 | CE9: PnL | CF9: =IF(CF3>CF1,CF11,(CF1-CF3)*CF7*330+CF11) -> -532950 | CH9: PnL | CI9: =IF(CI3>CI1,(CI3-CI1)*CI7*330+CI11,CI11) -> 224730 | CK9: PnL | CL9: =IF(CL3>CL1,(CL3-CL1)*CL7*330+CL11,CL11) -> 0 | CN9: PnL | CO9: =IF(CO3>CO1,CO11,(CO1-CO3)*CO7*330+CO11) -> -162360 | CQ9: PnL | CR9: =IF(CR3>CR1,(CR3-CR1)*CR7*330+CR11,CR11) -> -396000 | CT9: PnL | CU9: =IF(CU3>CU1,CU11,(CU1-CU3)*CU7*330+CU11) -> 0 | CW9: PnL | CX9: =IF(CX3>CX1,(CX3-CX1)*CX7*330+CX11,CX11) -> 488400 | CZ9: PnL | DA9: =IF(DA3>DA1,(DA3-DA1)*DA7*330+DA11,DA11) -> 0 | DC9: PnL | DD9: =IF(DD3>DD1,(DD3-DD1)*DD7*330+DD11,DD11) -> 0 | DF9: PnL | DG9: =IF(DG3>DG1,(DG3-DG1)*DG7*330+DG11,DG11) -> 0 | DI9: PnL | DJ9: =IF(DJ3>DJ1,DJ11,(DJ1-DJ3)*DJ7*330+DJ11) -> 0 | DL9: PnL | DM9: =IF(DM3>DM1,(DM3-DM1)*DM7*330+DM11,DM11) -> 0 | DO9: PnL | DP9: =IF(DP3>DP1,DP11,(DP1-DP3)*DP7*330+DP11) -> 189420 | DR9: PnL | DS9: =IF(DS3>DS1,(DS3-DS1)*DS7*330+DS11,DS11) -> 206250 | DU9: PnL | DV9: =IF(DV3>DV1,DV11,(DV1-DV3)*DV7*330+DV11) -> 0 | DX9: PnL | DY9: =IF(DY3>DY1,(DY3-DY1)*DY7*330+DY11,DY11) -> 0 | EA9: PnL | EB9: =IF(EB3>EB1,EB11,(EB1-EB3)*EB7*330+EB11) -> 294360 | ED9: PnL | EE9: =IF(EE3>EE1,(EE3-EE1)*EE7*330+EE11,EE11) -> 237930 | EG9: PnL | EH9: =IF(EH3>EH1,EH11,(EH1-EH3)*EH7*330+EH11) -> 125400 | EJ9: PnL | EK9: =IF(EK3>EK1,(EK3-EK1)*EK7*330+EK11,EK11) -> 107250 | EM9: PnL | EN9: =IF(EN3>EN1,EN11,(EN1-EN3)*EN7*330+EN11) -> 0 | EP9: PnL | EQ9: =IF(EQ3>EQ1,EQ11,(EQ1-EQ3)*EQ7*330+EQ11) -> 0 | ES9: PnL | ET9: =IF(ET3>ET1,(ET3-ET1)*ET7*330+ET11,ET11) -> 0 | EV9: PnL | EW9: =IF(EW3>EW1,EW11,(EW1-EW3)*EW7*330+EW11) -> 274230 | EY9: PnL | EZ9: =IF(EZ3>EZ1,EZ11,(EZ1-EZ3)*EZ7*330+EZ11) -> 120615 | FB9: PnL | FC9: =IF(FC3>FC1,(FC3-FC1)*FC7*330+FC11,FC11) -> 299970 | FE9: PnL | FF9: =IF(FF3>FF1,(FF3-FF1)*FF7*330+FF11,FF11) -> 149985 | FH9: PnL | FI9: =IF(FI3>FI1,FI11,(FI1-FI3)*FI7*330+FI11) -> 206250 | FK9: PnL | FL9: =IF(FL3>FL1,(FL3-FL1)*FL7*330+FL11,FL11) -> 231000 | FN9: PnL | FO9: =IF(FO3>FO1,(FO3-FO1)*FO7*330+FO11,FO11) -> 264000 | FQ9: PnL | FR9: =IF(FR3>FR1,FR11,(FR1-FR3)*FR7*330+FR11) -> 280500 | FY9: (@) Média | FZ9: =FZ8*17.5 -> 61250
G10: -30 | H10: 295.75 | J10: -50 | K10: 307.97 | L10: BTG | M10: -40 | N10: 321.36 | O10: BTG | P10: =-8910/330 -> -27 | Q10: 326 | R10: termo/rolagem | V10: 50 | W10: 319.98 | GB10: Saldo Hedge
J11: -100 | K11: =336.6-12.25 -> 324.35 | L11: rolagem/Oct | M11: -50 | N11: 319 | O11: BTG | P11: =-3395/330 -> -10.287879 | Q11: 326.15 | R11: termo/rolagem | BD11: Premio | BE11: =2.86*BE5*BE7*-1-10000 -> 271252.4 | BG11: Premio | BH11: =3.3*BH5*BH7*-1 -> 27225 | BJ11: Premio | BK11: =6.4*330*BK7*-1 -> 340032 | BM11: Premio | BN11: =5.8*BN5*BN7*-1 -> 278400 | BP11: Premio | BQ11: =8.2*330*BQ7*-1+26000 -> 174830 | BS11: Premio | BT11: =8.6*330*BT7*-1 -> 425700 | BV11: Premio | BW11: =(6.61+6.78)/2*330*BW7*-1 -> 441870 | BY11: Premio | BZ11: =8.16*BZ5*BZ7*-1 -> 269280 | CB11: Premio | CC11: =5.53*CC5*CC7*-1 -> 182490 | CE11: Premio | CF11: =9.85*330*CF7*-1 -> 325050 | CH11: Premio | CI11: =6.81*CI5*CI7*-1 -> 224730 | CK11: Premio | CL11: =8.16*CL5*CL7*-1 -> 0 | CN11: Premio | CO11: =9*330*CO7*-1 -> 487080 | CQ11: Premio | CR11: =3*CR5*CR7*-1 -> -396000 | CT11: Premio | CU11: =3.98*330*CU7*-1 -> 0 | CW11: Premio | CX11: =1.85*CX5*CX7*-1 -> 488400 | CZ11: Premio | DA11: =7.6136*DA5*DA7*-1 -> 0 | DC11: Premio | DD11: =8.5*DD5*DD7*-1 -> 0 | DF11: Premio | DG11: =4.952*DG5*DG7*-1 -> 0 | DI11: Premio | DJ11: =2.45*330*DJ7*-1 -> 0 | DL11: Premio | DM11: =2.71*DM5*DM7*-1 -> 0 | DO11: Premio | DP11: =11.48*330*DP7*-1 -> 189420 | DR11: Premio | DS11: =12.5*DS5*DS7*-1 -> 206250 | DU11: Premio | DV11: =3.42*330*DV7*-1 -> 0 | DX11: Premio | DY11: =5.48*DY5*DY7*-1 -> 0 | EA11: Premio | EB11: =8.92*330*EB7*-1 -> 294360 | ED11: Premio | EE11: =7.21*EE5*EE7*-1 -> 237930 | EG11: Premio | EH11: =7.6*330*EH7*-1 -> 125400 | EJ11: Premio | EK11: =6.5*EK5*EK7*-1 -> 107250 | EM11: Premio | EN11: =3.45*330*EN7*-1 -> 0 | EP11: Premio | EQ11: =5*330*EQ7*-1 -> 0 | ES11: Premio | ET11: =5.1*ET5*ET7*-1 -> 0 | EV11: Premio | EW11: =8.31*330*EW7*-1 -> 274230 | EY11: Premio | EZ11: =7.31*330*EZ7*-1 -> 120615 | FB11: Premio | FC11: =9.09*FC5*FC7*-1 -> 299970 | FE11: Premio | FF11: =9.09*FF5*FF7*-1 -> 149985 | FH11: Premio | FI11: =7.5*330*FI7*-1 -> 247500 | FK11: Premio | FL11: =7*FL5*FL7*-1 -> 231000 | FN11: Premio | FO11: =8*FO5*FO7*-1 -> 264000 | FQ11: Premio | FR11: =8.5*330*FR7*-1 -> 280500 | FY11: (@) TOTAL | FZ11: =FZ6+FZ9 -> 358750 | GB11: Cts | GC11: =GC5+GC8 -> 422.14242
J12: -50 | K12: 300.4 | L12: BTG | M12: -20 | N12: 315.5 | P12: =-2310/330 -> -7 | Q12: 327 | R12: termo/rolagem | BE12: liquidada | BH12: liquidada | BK12: liquidada | BN12: ok | BQ12: ok | BT12: ok | BW12: ok | BZ12: ok | CC12: ok | CF12: ok | CI12: ok | CO12: ok | CR12: ok | CX12: ok | DP12: ok | DS12: ok | EB12: ok | EE12: ok | EH12: ok | EK12: ok | EW12: ok | EZ12: ok | FC12: ok | FF12: ok | FI12: ok | FL12: ok | FO12: ok | FR12: ok
J13: 70 | K13: 304 | L13: BTG | M13: =-660/330 -> -2 | N13: 324.35 | P13: =-660/330 -> -2 | Q13: 331.35 | R13: termo/rolagem
J14: 33 | K14: 304.95 | L14: BTG | M14: =-3300/330 -> -10 | N14: 324 | P14: =-3300/330 -> -10 | Q14: 331 | R14: termo/rolagem | EB14: 8.92 | EE14: 7.21 | EH14: 7.6 | EK14: 6.5 | EW14: 8.31 | EZ14: 7.31 | FC14: 9.09 | FF14: 9.09 | FI14: 7.5 | FL14: 7 | FO14: 8 | FR14: 8.5
J15: 25 | K15: 302.5 | M15: =-7920/330 -> -24 | N15: 325.15 | P15: =-990/330 -> -3 | Q15: 332 | R15: termo/rolagem
J16: =-50+45 -> -5 | K16: =330-7 -> 323 | L16: termo/rolagem | M16: -30 | N16: 304 | P16: =-7920/330 -> -24 | Q16: 332.15 | R16: termo/rolagem | EA16: Put dez | ED16: Call dez | EV16: Put jan | EY16: Call jan | FH16: Put fev | FK16: Call fev | FN16: Call mar | FQ16: Put mar
J17: -7 | K17: 317 | L17: BTG | P17: =-5940/330 -> -18 | Q17: 327.5 | R17: termo/rolagem | EA17: Preço médio | EB17: =(EB7*EB1+EH7*EH1)/(EB7+EH7) -> 320 | ED17: Preço médio | EE17: =(EE7*EE1+EK7*EK1)/(EE7+EK7) -> 335 | EV17: Preço médio | EW17: =(EW7*EW1+EZ7*EZ1)/(EW7+EZ7) -> 320 | EY17: Preço médio | EZ17: =(FC7*FC1+FF7*FF1)/(FC7+FF7) -> 335 | FH17: Preço médio | FI17: =(FI7*FI1)/(FI7) -> 325 | FK17: Preço médio | FL17: =(FL7*FL1)/(FL7) -> 335 | FN17: Preço médio | FO17: =(FO7*FO1)/(FO7) -> 335 | FQ17: Preço médio | FR17: =(FR7*FR1)/(FR7) -> 325
J18: -18 | K18: 317 | L18: BTG | R18: verificar posição no Aug | EA18: Prêmio médio | EB18: =(EB7*EB14+EH7*EH14)/(EB7+EH7) -> 8.48 | ED18: Prêmio médio | EE18: =(EE7*EE14+EK7*EK14)/(EE7+EK7) -> 6.9733333 | EV18: Prêmio médio | EW18: =(EW7*EW14+EZ7*EZ14)/(EW7+EZ7) -> 7.9766667 | EY18: Prêmio médio | EZ18: =(FC7*FC14+FF7*FF14)/(FC7+FF7) -> 9.09 | FH18: Prêmio médio | FI18: =FI14 -> 7.5 | FK18: Prêmio médio | FL18: =FL14 -> 7 | FN18: Prêmio médio | FO18: =FO14 -> 8 | FQ18: Prêmio médio | FR18: =FR14 -> 8.5
R19: verificar posição no Aug | EA19: Contratos | EB19: =EB7+EH7 -> -150 | ED19: Contratos | EE19: =EE7+EK7 -> -150 | EV19: Contratos | EW19: =EW7+EZ7 -> -150 | EY19: Contratos | EZ19: =FC7+FF7 -> -150 | FH19: Contratos | FI19: =FI7 -> -100 | FK19: Contratos | FL19: =FL7 -> -100 | FN19: Contratos | FO19: =FO7 -> -100 | FQ19: Contratos | FR19: =FR7 -> -100
R20: verificar posição rolada pra Set | BD20: IR TRADE
AW21: Abril | BD21: BTG | BE21: =90664-34 -> 90630 | BF21: ok | EA21: Put jan | ED21: Call jan
AW22: Maio | BD22: BTG | BE22: =-45519-6613+50752+66395 -> 65015 | BF22: ok | EA22: Preço médio | EB22: =(EB12*EB6+EH12*EH6)/(EB12+EH12) -> #VALUE! | ED22: Preço médio | EE22: =(EE12*EE6+EK12*EK6)/(EE12+EK12) -> #VALUE!
AW23: Junho | BD23: BTG | BE23: =-66562-193426+296882+323386+6433 -> 366713 | BF23: ok | EA23: Prêmio médio | EB23: =(EB12*EB19+EH12*EH19)/(EB12+EH12) -> #VALUE! | ED23: Prêmio médio | EE23: =(EE12*EE19+EK12*EK19)/(EE12+EK12) -> #VALUE!
AW24: Julho | BD24: BTG | BE24: -1269830 | BF24: ok | EA24: Contratos | EB24: =EB12+EH12 -> #VALUE! | ED24: Contratos | EE24: =EE12+EK12 -> #VALUE!
AW25: Agosto | BD25: BTG | BE25: =203629+4404 -> 208033 | BF25: ok
AW26: Setembro | BD26: BTG | BE26: -433527 | BF26: ok | EA26: Put fev | ED26: Call fev
A27: =SUM(A2:A25) -> 0 | B27: =SUMPRODUCT(A2:A25,B2:B25)/A27 -> #DIV/0! | D27: =SUM(D2:D25) -> 200 | E27: =SUMPRODUCT(D2:D25,E2:E25)/D27 -> 317.69 | G27: =SUM(G2:G25) -> -380 | H27: =SUMPRODUCT(G2:G25,H2:H25)/G27 -> 311.19095 | J27: =SUM(J2:J23) -> -238 | K27: =SUMPRODUCT(J2:J23,K2:K23)/J27 -> 327.58298 | M27: =SUM(M2:M25) -> -131 | N27: =SUMPRODUCT(M2:M25,N2:N25)/M27 -> 327.21221 | P27: =SUM(P2:P26) -> -143.28788 | Q27: =SUMPRODUCT(P2:P26,Q2:Q26)/P27 -> 333.14431 | S27: =SUM(S2:S25) -> -256.69091 | T27: =SUMPRODUCT(S2:S25,T2:T25)/S27 -> 328.36723 | V27: =SUM(V2:V25) -> -162.90909 | W27: =SUMPRODUCT(V2:V25,W2:W25)/V27 -> 330.5034 | Y27: =SUM(Y2:Y25) -> -200 | Z27: =SUMPRODUCT(Y2:Y25,Z2:Z25)/Y27 -> 327.88625 | AB27: =SUM(AB2:AB25) -> -100 | AC27: =SUMPRODUCT(AB2:AB25,AC2:AC25)/AB27 -> 329.4 | AE27: =SUM(AE2:AE25) -> -150 | AF27: =SUMPRODUCT(AE2:AE25,AF2:AF25)/AE27 -> 329.7272 | AW27: Outubro | BD27: BTG | BE27: =-445464+117791 -> -327673 | BF27: ok | EA27: Preço médio | EB27: =(EB17*EB11+EH17*EH11)/(EB17+EH17) -> 294360 | ED27: Preço médio | EE27: =(EE17*EE11+EK17*EK11)/(EE17+EK17) -> 237930
B28: zerado | EA28: Prêmio médio | EB28: =(EB17*EB24+EH17*EH24)/(EB17+EH17) -> #VALUE! | ED28: Prêmio médio | EE28: =(EE17*EE24+EK17*EK24)/(EE17+EK17) -> #VALUE!
C29: Call | D29: =BE7+BH7 -> -323 | F29: Call | G29: =BN7 -> -150 | I29: Call | J29: =BZ7+CC7 -> -200 | L29: Call | M29: =CI7 -> -100 | O29: Call | P29: =DG7+DD7+DA7+CX7+CL7+CR7+DM7 -> -400 | R29: Call | S29: =DS7+DY7 -> -50 | U29: Call | V29: =EE7+EK7+ET7 -> -150 | X29: Call | Y29: =FC7+FF7 -> -150 | AA29: Call | AB29: =FL7 -> -100 | AD29: Call | AE29: =FO7 -> -100 | EA29: Contratos | EB29: =EB17+EH17 -> 320 | ED29: Contratos | EE29: =EE17+EK17 -> 335
C30: Delta | D30: 0.75 | F30: Delta | G30: 1e-05 | I30: Delta | J30: 0.3 | L30: Delta | M30: 1e-06 | O30: Delta | P30: 0.05 | R30: Delta | S30: 0.5 | U30: Delta | V30: 0.05 | X30: Delta | Y30: 0.45 | AA30: Delta | AB30: 0.45 | AD30: Delta | AE30: 0.45
C31: Delta Calls | D31: =D29*D30 -> -242.25 | F31: Delta Calls | G31: =G29*G30 -> -0.0015 | I31: Delta Calls | J31: =J29*J30 -> -60 | L31: Delta Calls | M31: =M29*M30 -> -0.0001 | O31: Delta Calls | P31: =P29*P30 -> -20 | R31: Delta Calls | S31: =S29*S30 -> -25 | U31: Delta Calls | V31: =V29*V30 -> -7.5 | X31: Delta Calls | Y31: =Y29*Y30 -> -67.5 | AA31: Delta Calls | AB31: =AB29*AB30 -> -45 | AD31: Delta Calls | AE31: =AE29*AE30 -> -45 | EA31: Put mar | ED31: Call mar
EA32: Preço médio | EB32: =(EB22*EB16+EH22*EH16)/(EB22+EH22) -> #VALUE! | ED32: Preço médio | EE32: =(EE22*EE16+EK22*EK16)/(EE22+EK22) -> #VALUE!
C33: Put | D33: =BK7 -> -161 | F33: Put | G33: =BQ7+BT7 -> -205 | I33: Put | J33: =BW7 -> -200 | L33: Put | M33: =CF7 -> -100 | O33: Put | P33: =CO7+CU7+DJ7 -> -164 | R33: Put | S33: =DV7+DY7+DP7 -> -50 | U33: Put | V33: =EB7+EH7+EN7+EQ7 -> -150 | X33: Put | Y33: =EW7+EZ7 -> -150 | AA33: Put | AB33: =FI7 -> -100 | AD33: Put | AE33: =FR7 -> -100 | EA33: Prêmio médio | EB33: =(EB22*EB29+EH22*EH29)/(EB22+EH22) -> #VALUE! | ED33: Prêmio médio | EE33: =(EE22*EE29+EK22*EK29)/(EE22+EK22) -> #VALUE!
C34: Delta | D34: 0.35 | F34: Delta | G34: 1 | I34: Delta | J34: 0.75 | L34: Delta | M34: 1 | O34: Delta | P34: 0.3 | R34: Delta | S34: 0.15 | U34: Delta | V34: 0.5 | X34: Delta | Y34: 0.45 | AA34: Delta | AB34: 0.35 | AD34: Delta | AE34: 0.35 | EA34: Contratos | EB34: =EB22+EH22 -> #VALUE! | ED34: Contratos | EE34: =EE22+EK22 -> #VALUE!
C35: Delta Puts | D35: =D33*D34*-1 -> 56.35 | F35: Delta Puts | G35: =G33*G34*-1 -> 205 | I35: Delta Puts | J35: =J33*J34*-1 -> 150 | L35: Delta Puts | M35: =M33*M34*-1 -> 100 | O35: Delta Puts | P35: =P33*P34*-1 -> 49.2 | R35: Delta Puts | S35: =S33*S34*-1 -> 7.5 | U35: Delta Puts | V35: =V33*V34*-1 -> 75 | X35: Delta Puts | Y35: =Y33*Y34*-1 -> 67.5 | AA35: Delta Puts | AB35: =AB33*AB34*-1 -> 35 | AD35: Delta Puts | AE35: =AE33*AE34*-1 -> 35
C37: Futuro | D37: =D27 -> 200 | F37: Futuro | G37: =G27 -> -380 | I37: Futuro | J37: =J27 -> -238 | L37: Futuro | M37: =M27 -> -131 | O37: Futuro | P37: =P27 -> -143.28788 | R37: Futuro | S37: =S27 -> -256.69091 | U37: Futuro | V37: =V27 -> -162.90909 | X37: Futuro | Y37: =Y27 -> -200 | AA37: Futuro | AB37: =AB27 -> -100 | AD37: Futuro | AE37: =AE27 -> -150
AW38: Abr - Jul | BE38: =SUM(BE21:BE36) -> -1300639
C39: Delta Geral | D39: =D37+D35+D31 -> 14.1 | F39: Delta Geral | G39: =G37+G35+G31 -> -175.0015 | I39: Delta Geral | J39: =J37+J35+J31 -> -148 | L39: Delta Geral | M39: =M37+M35+M31 -> -31.0001 | O39: Delta Geral | P39: =P37+P35+P31 -> -114.08788 | R39: Delta Geral | S39: =S37+S35+S31 -> -274.19091 | U39: Delta Geral | V39: =V37+V35+V31 -> -95.409091 | X39: Delta Geral | Y39: =Y37+Y35+Y31 -> -200 | AB39: =AB37+AB35+AB31 -> -110 | AE39: =AE37+AE35+AE31 -> -160 | AW39: Alocado | BE39: =SUM(GJ6:GJ1048576) -> 0
AW40: Delta | BE40: =BE38-BE39 -> -1300639
C41: (@) Físico | D41: =(6525+4200)/330 -> 32.5 | F41: (@) Físico | G41: =(30495-2600+106000-13000)/330 -> 366.34848 | I41: (@) Físico | J41: =(8200+119000)/330 -> 385.45455 | L41: (@) Físico | M41: =(55062+8775)/330 -> 193.44545 | O41: (@) Físico | P41: =(25160+1800+820)/330 -> 84.181818 | R41: (@) Físico | S41: =(77630+9135+13770+1700)/330 -> 309.80303 | U41: (@) Físico | V41: =(76700+3240+1950)/330 -> 248.15152 | X41: (@) Físico | Y41: =(52300+400+3400+54000)/330 -> 333.63636 | AA41: (@) Físico | AB41: =(102000+40000)/330 -> 430.30303 | AD41: (@) Físico | AE41: =(19000+7500+45000)/330 -> 216.66667
...
